<?xml version="1.0"?>
<!-- Basic BlueBoat with Gazebo plugins for dynamics -->
<robot xmlns:xacro="http://ros.org/wiki/xacro" name="BlueBoat">

  <xacro:arg name="locked" default="false" />
  <xacro:arg name="thruster_config" default="H" />
  <xacro:arg name="camera_enabled" default="false" />
  <xacro:arg name="gps_enabled" default="false" />
  <xacro:arg name="imu_enabled" default="false" />
  <xacro:arg name="lidar_enabled" default="false" />
  <xacro:arg name="sonar_enabled" default="false" />
  <xacro:arg name="ground_truth_enabled" default="false" />
  <xacro:arg name="all_sensors_enabled" default="false" />
  <xacro:arg name="pinger_enabled" default="false" />
  <xacro:arg name="ball_shooter_enabled" default="false" />
  <xacro:arg name="thruster_namespace" default="thrusters/"/>
  <xacro:arg name="camera_namespace" default="cameras/"/>  
  <xacro:arg name="sensor_namespace" default="sensors/"/>
  <xacro:arg name="pinger_namespace" default="pingers/"/>
  <xacro:arg name="shooter_namespace" default="shooters/"/>
  <!-- Note: this is only used for some sensors that do not correctly use the 
  robotNamespace parameter -->
  <xacro:arg name="namespace" default="blueboat"/>    
  <xacro:property name="thruster_namespace" value="$(arg thruster_namespace)" scope="global" />
  <xacro:property name="camera_namespace" value="$(arg camera_namespace)" scope="global" />
  <xacro:property name="sensor_namespace" value="$(arg sensor_namespace)" scope="global" />
  <xacro:property name="pinger_namespace" value="$(arg pinger_namespace)" scope="global" />
  <xacro:property name="shooter_namespace" value="$(arg shooter_namespace)" scope="global" />
  <xacro:property name="namespace" value="$(arg namespace)" scope="global" />  
 
  <!-- Sensor yaml file -->
  <xacro:arg name="yaml_component_generation" default="false"/>
  <xacro:arg name="component_xacro_file" default = ""/>

  <!-- Thruster yaml file -->
  <xacro:arg name="yaml_thruster_generation" default="false"/>
  <xacro:arg name="thruster_xacro_file" default = ""/>
  
  <!-- === The BlueBoat platform === -->
  <xacro:include filename="$(find blueboat)/urdf/blueboat_gazebo.xacro"/>
  

  <!-- === Thrusters === -->
  <xacro:if value="$(arg yaml_thruster_generation)">
    <xacro:blueboat thruster_layout="$(arg thruster_xacro_file)"/>
  </xacro:if>

  <xacro:unless value="$(arg yaml_thruster_generation)">
    <xacro:property name="thruster_conf" value="$(arg thruster_config)"/>
    
    <xacro:if value="${thruster_conf == 'H'}">
       <xacro:blueboat thruster_layout="$(find blueboat)/urdf/thrusters/aft_thrusters_layout.xacro"/>
    </xacro:if>

    <xacro:if value="${thruster_conf == 'T'}">
      <xacro:blueboat thruster_layout="$(find blueboat)/urdf/thruster_layouts/blueboat_t_thrusters.xacro"/>
    </xacro:if>

    <xacro:if value="${thruster_conf == 'X'}">
      <xacro:blueboat thruster_layout="$(find blueboat)/urdf/thruster_layouts/blueboat_x_thrusters.xacro"/>
    </xacro:if>
  </xacro:unless>
    

  <!-- === Decide if we lock the robot to the world === -->
  <xacro:if value="$(arg locked)">
    <gazebo>
      <link name="blueboat_external_link"/>
      <joint name="blueboat_external_pivot_joint" type="universal">
        <parent>blueboat::blueboat/base_link</parent>
        <child>blueboat_external_link</child>
        <axis>
          <xyz>1 0 0</xyz>
        </axis>
        <axis2>
          <xyz>0 1 0</xyz>
        </axis2>
      </joint>
      <joint name="blueboat_external_riser" type="prismatic">
        <parent>world</parent>
        <child>blueboat_external_link</child>
        <axis>
          <limit>
            <lower>-3</lower>
            <upper>3</upper>
          </limit>
          <xyz>0 0 1</xyz>
        </axis>
      </joint>
    </gazebo>
  </xacro:if>

  <!-- === Sensors === -->
  <!-- Use sensor yaml file if given -->
  <xacro:if value="$(arg yaml_component_generation)">
    <xacro:include filename="$(arg component_xacro_file)"/>
    <xacro:yaml_components />
  </xacro:if>
  
  <xacro:unless value="$(arg yaml_component_generation)">

    <!-- Add simulated Camera -->
    <xacro:if value="$(arg camera_enabled)">
      <xacro:blueboat_camera name="front_camera" x="0.32" y="0" z="0.125" P="${radians(0)}" />
    </xacro:if>
    
    <!-- Add simulated GPS -->
    <xacro:if value="$(arg gps_enabled)">
      <xacro:blueboat_gps name="gps_blueboat"  x="0.15" y="-0.37" z="0.125" />
    </xacro:if>
    
    <!-- Add Simulated IMU -->
    <xacro:if value="$(arg imu_enabled)">
      <xacro:blueboat_imu name="imu_blueboat" x="0" y="0" z="0.25" />
    </xacro:if>
    
    <!-- Add 3D LIDAR -->
    <xacro:if value="$(arg lidar_enabled)">
      <xacro:lidar name="lidar_blueboat" x="0" y="0" z="0.5" type="32_beam"/>
    </xacro:if>
    
    <!-- Add P3D ground truth -->
    <xacro:if value="$(arg ground_truth_enabled)">
      <xacro:blueboat_p3d name="p3d_blueboat"/>
    </xacro:if>

    <!-- Add pinger -->
    <xacro:if value="$(arg pinger_enabled)">
      <xacro:blueboat_pinger name="pinger" position="0 0 -0.23" />
    </xacro:if>
    
    <!-- Add 2D SONAR -->
    <xacro:if value="$(arg sonar_enabled)">
      <xacro:blueboat_multibeam_laser name="sonar" x="-0.2" y="0.25" z="-0.28"/>
    </xacro:if>

    <!-- ==== Sensor configuration ==== -->
    <xacro:if value="$(arg all_sensors_enabled)">
       
      <!-- Add a camera facing front -->
      <xacro:blueboat_camera name="front_camera" x="0.32" y="0" z="0.125" P="${radians(0)}" />
    
      <!-- Add simulated GPS -->
      <xacro:blueboat_gps name="gps_blueboat"  x="0.15" y="-0.37" z="0.125" />
    
      <!-- Add Simulated IMU -->
      <xacro:blueboat_imu name="imu_blueboat" x="0" y="0" z="0.25" />
    
      <!-- Add 3D LIDAR -->
      <xacro:lidar name="lidar_blueboat" x="0" y="0" z="0.5" type="32_beam"/>

      <!-- Add pinger -->
      <xacro:blueboat_pinger name="pinger" position="0 0 -0.23" />
      
      <!-- Add Sonar -->
      <xacro:blueboat_multibeam_laser name="sonar" x="-0.2" y="0.25" z="-0.28"/>
      
      <!-- Add Ground Truth -->
      <xacro:blueboat_p3d name="p3d_blueboat"/>

    </xacro:if>
  </xacro:unless>

</robot>

